Workbook

Sheet Leia-me
A1: Planilha auditável de pontuação (AI Maturity Assessment)
A3: O que é
B4: Esta planilha cobre todas as 158 questões e 28 capabilities do framework.json e calcula os scores com fórmulas SUMPRODUCT visíveis, idênticas ao algoritmo oficial descrito em referencia/pontuacao-e-calculo.md e implementado em scripts/compute_scores.py.
A6: Como usar
B7: 1. Na aba "Respostas", preencha a coluna "Nível" (0 a 4) para cada questão respondida. Deixe em branco as questões sem resposta.
B8: 2. Registre a evidência de cada resposta na coluna "Evidência".
B9: 3. A aba "Cálculo" atualiza automaticamente: score por capability, por pilar, overall, rótulos de maturidade e o threshold de cobertura.
B10: 4. Não edite as colunas de peso: os pesos vêm do framework.json, a fonte única da verdade. Para regenerar ou pré-popular esta planilha use scripts/generate_scoring_workbook.py.
A12: Como o score é calculado
B13: Capability: soma(nível x peso da questão) / soma(pesos das questões respondidas). Questões em branco não somam no numerador nem no denominador.
B14: Pilar: soma(score da capability x peso da capability) / soma(pesos), considerando apenas capabilities com ao menos 1 resposta.
B15: Overall: mesmo SUMPRODUCT aplicado sobre TODAS as capabilities do framework. Não é a média dos 3 pilares.
A17: Rótulos de maturidade
A18: Faixa de score | B18: Rótulo
A19: score < 0.5 | B19: L0 — Inicial
A20: 0.5 <= score < 1.5 | B20: L1 — Em Desenvolvimento
A21: 1.5 <= score < 2.5 | B21: L2 — Definido
A22: 2.5 <= score < 3.5 | B22: L3 — Gerenciado
A23: score >= 3.5 | B23: L4 — Otimizando
A25: Threshold de cobertura
A26: Questões respondidas | B26: Status
A27: >= 40 | B27: OK: scoring normal
A28: 25 a 39 | B28: WARNING: resultado preliminar, confiabilidade limitada
A29: < 25 | B29: BLOCKED: cobertura insuficiente, não usar para decisões executivas

Sheet Respostas
A1: QID | B1: Pilar | C1: Capability | D1: Pergunta | E1: Peso | F1: Nível | G1: Evidência
A2: P1-C1-Q1 | B2: P1 | C2: P1-C1 | D2: Em que medida sua organização utiliza ferramentas de completação de código com IA (ex. GitHub Copilot)? | E2: 1
A3: P1-C1-Q2 | B3: P1 | C3: P1-C1 | D3: Quão efetivamente sua equipe aproveita IA para revisão de código e melhoria de qualidade? | E3: 1
A4: P1-C1-Q3 | B4: P1 | C4: P1-C1 | D4: Como sua organização mede e rastreia o impacto das ferramentas de codificação IA na produtividade? | E4: 0.8
A5: P1-C1-Q4 | B5: P1 | C5: P1-C1 | D5: Qual nível de capacidades de testes assistidos por IA sua organização emprega? | E5: 1
A6: P1-C1-Q5 | B6: P1 | C6: P1-C1 | D6: Como sua organização governa o código gerado por IA em termos de segurança e conformidade? | E6: 1.1
A7: P1-C2-Q1 | B7: P1 | C7: P1-C2 | D7: Quão maduro é seu portal ou plataforma interna para desenvolvedores? | E7: 1
A8: P1-C2-Q2 | B8: P1 | C8: P1-C2 | D8: Quão efetivamente suas equipes usam ambientes de desenvolvimento padronizados? | E8: 0.9
A9: P1-C2-Q3 | B9: P1 | C9: P1-C2 | D9: Em que medida Plataforma de Experiência do Desenvolvedor (self-service IDP) foi adotado entre as equipes? | E9: 1
A10: P1-C2-Q4 | B10: P1 | C10: P1-C2 | D10: Em que medida Plataforma de Experiência do Desenvolvedor (golden paths and templates) foi adotado entre as equipes? | E10: 1
A11: P1-C2-Q5 | B11: P1 | C11: P1-C2 | D11: Em que medida Plataforma de Experiência do Desenvolvedor (developer portal) foi adotado entre as equipes? | E11: 1
A12: P1-C2-Q6 | B12: P1 | C12: P1-C2 | D12: Em que medida Plataforma de Experiência do Desenvolvedor (paved road policy enforcement) foi adotado entre as equipes? | E12: 1
A13: P1-C3-Q1 | B13: P1 | C13: P1-C3 | D13: Quão efetivamente sua organização captura e compartilha conhecimento de desenvolvimento? | E13: 1
... A159: P3-C9-Q5 | B159: P3 | C159: P3-C9 | D159: Em que medida FinOps e Otimização de Custos (unit economics per product) foi adotado entre as equipes? | E159: 1

Sheet Cálculo
A1: Cálculo oficial (SUMPRODUCT sobre a aba Respostas)
A3: ID | B3: Nome | C3: Pilar | D3: Peso | E3: Respondidas | F3: Aplicáveis | G3: Soma ponderada | H3: Peso respondido | I3: Score | J3: Rótulo | K3: Contrib. numerador | L3: Contrib. denominador
A4: P1-C1 | B4: Assistentes de Codificação IA | C4: P1 | D4: 1.2 | E4: =COUNT(Respostas!F2:F6) | F4: 5 | G4: =SUMPRODUCT(Respostas!F2:F6,Respostas!E2:E6) | H4: =SUMPRODUCT(--(Respostas!F2:F6<>""),Respostas!E2:E6) | I4: =IF(H4=0,"",G4/H4) | J4: =IF(I4="","Sem resposta",LOOKUP(I4,{0,0.5,1.5,2.5,3.5},{"L0 — Inicial","L1 — Em Desenvolvimento","L2 — Definido","L3 — Gerenciado","L4 — Otimizando"})) | K4: =IF(H4=0,0,D4*I4) | L4: =IF(H4=0,0,D4)
A5: P1-C2 | B5: Plataforma de Experiência do Desenvolvedor | C5: P1 | D5: 1 | E5: =COUNT(Respostas!F7:F12) | F5: 6 | G5: =SUMPRODUCT(Respostas!F7:F12,Respostas!E7:E12) | H5: =SUMPRODUCT(--(Respostas!F7:F12<>""),Respostas!E7:E12) | I5: =IF(H5=0,"",G5/H5) | J5: =IF(I5="","Sem resposta",LOOKUP(I5,{0,0.5,1.5,2.5,3.5},{"L0 — Inicial","L1 — Em Desenvolvimento","L2 — Definido","L3 — Gerenciado","L4 — Otimizando"})) | K5: =IF(H5=0,0,D5*I5) | L5: =IF(H5=0,0,D5)
A6: P1-C3 | B6: Gestão do Conhecimento | C6: P1 | D6: 0.8 | E6: =COUNT(Respostas!F13:F18) | F6: 6 | G6: =SUMPRODUCT(Respostas!F13:F18,Respostas!E13:E18) | H6: =SUMPRODUCT(--(Respostas!F13:F18<>""),Respostas!E13:E18) | I6: =IF(H6=0,"",G6/H6) | J6: =IF(I6="","Sem resposta",LOOKUP(I6,{0,0.5,1.5,2.5,3.5},{"L0 — Inicial","L1 — Em Desenvolvimento","L2 — Definido","L3 — Gerenciado","L4 — Otimizando"})) | K6: =IF(H6=0,0,D6*I6) | L6: =IF(H6=0,0,D6)
A7: P1-C4 | B7: Automação de Revisão de Código | C7: P1 | D7: 1.1 | E7: =COUNT(Respostas!F19:F25) | F7: 7 | G7: =SUMPRODUCT(Respostas!F19:F25,Respostas!E19:E25) | H7: =SUMPRODUCT(--(Respostas!F19:F25<>""),Respostas!E19:E25) | I7: =IF(H7=0,"",G7/H7) | J7: =IF(I7="","Sem resposta",LOOKUP(I7,{0,0.5,1.5,2.5,3.5},{"L0 — Inicial","L1 — Em Desenvolvimento","L2 — Definido","L3 — Gerenciado","L4 — Otimizando"})) | K7: =IF(H7=0,0,D7*I7) | L7: =IF(H7=0,0,D7)
A8: P1-C5 | B8: Onboarding e Treinamento de Desenvolvedores | C8: P1 | D8: 0.9 | E8: =COUNT(Respostas!F26:F32) | F8: 7 | G8: =SUMPRODUCT(Respostas!F26:F32,Respostas!E26:E32) | H8: =SUMPRODUCT(--(Respostas!F26:F32<>""),Respostas!E26:E32) | I8: =IF(H8=0,"",G8/H8) | J8: =IF(I8="","Sem resposta",LOOKUP(I8,{0,0.5,1.5,2.5,3.5},{"L0 — Inicial","L1 — Em Desenvolvimento","L2 — Definido","L3 — Gerenciado","L4 — Otimizando"})) | K8: =IF(H8=0,0,D8*I8) | L8: =IF(H8=0,0,D8)
A9: P1-C6 | B9: Inner Source e Colaboração | C9: P1 | D9: 0.9 | E9: =COUNT(Respostas!F33:F38) | F9: 6 | G9: =SUMPRODUCT(Respostas!F33:F38,Respostas!E33:E38) | H9: =SUMPRODUCT(--(Respostas!F33:F38<>""),Respostas!E33:E38) | I9: =IF(H9=0,"",G9/H9) | J9: =IF(I9="","Sem resposta",LOOKUP(I9,{0,0.5,1.5,2.5,3.5},{"L0 — Inicial","L1 — Em Desenvolvimento","L2 — Definido","L3 — Gerenciado","L4 — Otimizando"})) | K9: =IF(H9=0,0,D9*I9) | L9: =IF(H9=0,0,D9)
A10: P1-C7 | B10: Automação de Documentação | C10: P1 | D10: 0.8 | E10: =COUNT(Respostas!F39:F43) | F10: 5 | G10: =SUMPRODUCT(Respostas!F39:F43,Respostas!E39:E43) | H10: =SUMPRODUCT(--(Respostas!F39:F43<>""),Respostas!E39:E43) | I10: =IF(H10=0,"",G10/H10) | J10: =IF(I10="","Sem resposta",LOOKUP(I10,{0,0.5,1.5,2.5,3.5},{"L0 — Inicial","L1 — Em Desenvolvimento","L2 — Definido","L3 — Gerenciado","L4 — Otimizando"})) | K10: =IF(H10=0,0,D10*I10) | L10: =IF(H10=0,0,D10)
A11: P1-C8 | B11: Medição de Produtividade do Desenvolvedor | C11: P1 | D11: 1 | E11: =COUNT(Respostas!F44:F49) | F11: 6 | G11: =SUMPRODUCT(Respostas!F44:F49,Respostas!E44:E49) | H11: =SUMPRODUCT(--(Respostas!F44:F49<>""),Respostas!E44:E49) | I11: =IF(H11=0,"",G11/H11) | J11: =IF(I11="","Sem resposta",LOOKUP(I11,{0,0.5,1.5,2.5,3.5},{"L0 — Inicial","L1 — Em Desenvolvimento","L2 — Definido","L3 — Gerenciado","L4 — Otimizando"})) | K11: =IF(H11=0,0,D11*I11) | L11: =IF(H11=0,0,D11)
A12: P1-C9 | B12: Automação de Ambientes e Espaços de Trabalho | C12: P1 | D12: 0.9 | E12: =COUNT(Respostas!F50:F54) | F12: 5 | G12: =SUMPRODUCT(Respostas!F50:F54,Respostas!E50:E54) | H12: =SUMPRODUCT(--(Respostas!F50:F54<>""),Respostas!E50:E54) | I12: =IF(H12=0,"",G12/H12) | J12: =IF(I12="","Sem resposta",LOOKUP(I12,{0,0.5,1.5,2.5,3.5},{"L0 — Inicial","L1 — Em Desenvolvimento","L2 — Definido","L3 — Gerenciado","L4 — Otimizando"})) | K12: =IF(H12=0,0,D12*I12) | L12: =IF(H12=0,0,D12)
A13: P2-C1 | B13: Inteligência de Pipeline CI/CD | C13: P2 | D13: 1.2 | E13: =COUNT(Respostas!F55:F60) | F13: 6 | G13: =SUMPRODUCT(Respostas!F55:F60,Respostas!E55:E60) | H13: =SUMPRODUCT(--(Respostas!F55:F60<>""),Respostas!E55:E60) | I13: =IF(H13=0,"",G13/H13) | J13: =IF(I13="","Sem resposta",LOOKUP(I13,{0,0.5,1.5,2.5,3.5},{"L0 — Inicial","L1 — Em Desenvolvimento","L2 — Definido","L3 — Gerenciado","L4 — Otimizando"})) | K13: =IF(H13=0,0,D13*I13) | L13: =IF(H13=0,0,D13)
A14: P2-C2 | B14: Infraestrutura como Código | C14: P2 | D14: 1.1 | E14: =COUNT(Respostas!F61:F66) | F14: 6 | G14: =SUMPRODUCT(Respostas!F61:F66,Respostas!E61:E66) | H14: =SUMPRODUCT(--(Respostas!F61:F66<>""),Respostas!E61:E66) | I14: =IF(H14=0,"",G14/H14) | J14: =IF(I14="","Sem resposta",LOOKUP(I14,{0,0.5,1.5,2.5,3.5},{"L0 — Inicial","L1 — Em Desenvolvimento","L2 — Definido","L3 — Gerenciado","L4 — Otimizando"})) | K14: =IF(H14=0,0,D14*I14) | L14: =IF(H14=0,0,D14)
A15: P2-C3 | B15: Observabilidade e Monitoramento | C15: P2 | D15: 1 | E15: =COUNT(Respostas!F67:F72) | F15: 6 | G15: =SUMPRODUCT(Respostas!F67:F72,Respostas!E67:E72) | H15: =SUMPRODUCT(--(Respostas!F67:F72<>""),Respostas!E67:E72) | I15: =IF(H15=0,"",G15/H15) | J15: =IF(I15="","Sem resposta",LOOKUP(I15,{0,0.5,1.5,2.5,3.5},{"L0 — Inicial","L1 — Em Desenvolvimento","L2 — Definido","L3 — Gerenciado","L4 — Otimizando"})) | K15: =IF(H15=0,0,D15*I15) | L15: =IF(H15=0,0,D15)
A16: P2-C4 | B16: Integração de Segurança (DevSecOps) | C16: P2 | D16: 1.2 | E16: =COUNT(Respostas!F73:F78) | F16: 6 | G16: =SUMPRODUCT(Respostas!F73:F78,Respostas!E73:E78) | H16: =SUMPRODUCT(--(Respostas!F73:F78<>""),Respostas!E73:E78) | I16: =IF(H16=0,"",G16/H16) | J16: =IF(I16="","Sem resposta",LOOKUP(I16,{0,0.5,1.5,2.5,3.5},{"L0 — Inicial","L1 — Em Desenvolvimento","L2 — Definido","L3 — Gerenciado","L4 — Otimizando"})) | K16: =IF(H16=0,0,D16*I16) | L16: =IF(H16=0,0,D16)
A17: P2-C5 | B17: Estratégias de Release e Implantação | C17: P2 | D17: 1.1 | E17: =COUNT(Respostas!F79:F84) | F17: 6 | G17: =SUMPRODUCT(Respostas!F79:F84,Respostas!E79:E84) | H17: =SUMPRODUCT(--(Respostas!F79:F84<>""),Respostas!E79:E84) | I17: =IF(H17=0,"",G17/H17) | J17: =IF(I17="","Sem resposta",LOOKUP(I17,{0,0.5,1.5,2.5,3.5},{"L0 — Inicial","L1 — Em Desenvolvimento","L2 — Definido","L3 — Gerenciado","L4 — Otimizando"})) | K17: =IF(H17=0,0,D17*I17) | L17: =IF(H17=0,0,D17)
A18: P2-C6 | B18: Automação de Testes | C18: P2 | D18: 1.1 | E18: =COUNT(Respostas!F85:F91) | F18: 7 | G18: =SUMPRODUCT(Respostas!F85:F91,Respostas!E85:E91) | H18: =SUMPRODUCT(--(Respostas!F85:F91<>""),Respostas!E85:E91) | I18: =IF(H18=0,"",G18/H18) | J18: =IF(I18="","Sem resposta",LOOKUP(I18,{0,0.5,1.5,2.5,3.5},{"L0 — Inicial","L1 — Em Desenvolvimento","L2 — Definido","L3 — Gerenciado","L4 — Otimizando"})) | K18: =IF(H18=0,0,D18*I18) | L18: =IF(H18=0,0,D18)
A19: P2-C7 | B19: Gestão de Incidentes e SRE | C19: P2 | D19: 1.1 | E19: =COUNT(Respostas!F92:F98) | F19: 7 | G19: =SUMPRODUCT(Respostas!F92:F98,Respostas!E92:E98) | H19: =SUMPRODUCT(--(Respostas!F92:F98<>""),Respostas!E92:E98) | I19: =IF(H19=0,"",G19/H19) | J19: =IF(I19="","Sem resposta",LOOKUP(I19,{0,0.5,1.5,2.5,3.5},{"L0 — Inicial","L1 — Em Desenvolvimento","L2 — Definido","L3 — Gerenciado","L4 — Otimizando"})) | K19: =IF(H19=0,0,D19*I19) | L19: =IF(H19=0,0,D19)
A20: P2-C8 | B20: Gestão de Artefatos e Pacotes | C20: P2 | D20: 0.9 | E20: =COUNT(Respostas!F99:F103) | F20: 5 | G20: =SUMPRODUCT(Respostas!F99:F103,Respostas!E99:E103) | H20: =SUMPRODUCT(--(Respostas!F99:F103<>""),Respostas!E99:E103) | I20: =IF(H20=0,"",G20/H20) | J20: =IF(I20="","Sem resposta",LOOKUP(I20,{0,0.5,1.5,2.5,3.5},{"L0 — Inicial","L1 — Em Desenvolvimento","L2 — Definido","L3 — Gerenciado","L4 — Otimizando"})) | K20: =IF(H20=0,0,D20*I20) | L20: =IF(H20=0,0,D20)
A21: P2-C9 | B21: Gestão de Mudanças e GitOps | C21: P2 | D21: 1 | E21: =COUNT(Respostas!F104:F108) | F21: 5 | G21: =SUMPRODUCT(Respostas!F104:F108,Respostas!E104:E108) | H21: =SUMPRODUCT(--(Respostas!F104:F108<>""),Respostas!E104:E108) | I21: =IF(H21=0,"",G21/H21) | J21: =IF(I21="","Sem resposta",LOOKUP(I21,{0,0.5,1.5,2.5,3.5},{"L0 — Inicial","L1 — Em Desenvolvimento","L2 — Definido","L3 — Gerenciado","L4 — Otimizando"})) | K21: =IF(H21=0,0,D21*I21) | L21: =IF(H21=0,0,D21)
A22: P2-C10 | B22: Segurança de Dependências e Cadeia de Suprimentos | C22: P2 | D22: 1.1 | E22: =COUNT(Respostas!F109:F113) | F22: 5 | G22: =SUMPRODUCT(Respostas!F109:F113,Respostas!E109:E113) | H22: =SUMPRODUCT(--(Respostas!F109:F113<>""),Respostas!E109:E113) | I22: =IF(H22=0,"",G22/H22) | J22: =IF(I22="","Sem resposta",LOOKUP(I22,{0,0.5,1.5,2.5,3.5},{"L0 — Inicial","L1 — Em Desenvolvimento","L2 — Definido","L3 — Gerenciado","L4 — Otimizando"})) | K22: =IF(H22=0,0,D22*I22) | L22: =IF(H22=0,0,D22)
A23: P3-C1 | B23: Arquitetura Cloud-Native | C23: P3 | D23: 1.1 | E23: =COUNT(Respostas!F114:F118) | F23: 5 | G23: =SUMPRODUCT(Respostas!F114:F118,Respostas!E114:E118) | H23: =SUMPRODUCT(--(Respostas!F114:F118<>""),Respostas!E114:E118) | I23: =IF(H23=0,"",G23/H23) | J23: =IF(I23="","Sem resposta",LOOKUP(I23,{0,0.5,1.5,2.5,3.5},{"L0 — Inicial","L1 — Em Desenvolvimento","L2 — Definido","L3 — Gerenciado","L4 — Otimizando"})) | K23: =IF(H23=0,0,D23*I23) | L23: =IF(H23=0,0,D23)
A24: P3-C2 | B24: Gestão de APIs | C24: P3 | D24: 0.9 | E24: =COUNT(Respostas!F119:F123) | F24: 5 | G24: =SUMPRODUCT(Respostas!F119:F123,Respostas!E119:E123) | H24: =SUMPRODUCT(--(Respostas!F119:F123<>""),Respostas!E119:E123) | I24: =IF(H24=0,"",G24/H24) | J24: =IF(I24="","Sem resposta",LOOKUP(I24,{0,0.5,1.5,2.5,3.5},{"L0 — Inicial","L1 — Em Desenvolvimento","L2 — Definido","L3 — Gerenciado","L4 — Otimizando"})) | K24: =IF(H24=0,0,D24*I24) | L24: =IF(H24=0,0,D24)
A25: P3-C3 | B25: Desenvolvimento de Aplicações IA | C25: P3 | D25: 1 | E25: =COUNT(Respostas!F124:F128) | F25: 5 | G25: =SUMPRODUCT(Respostas!F124:F128,Respostas!E124:E128) | H25: =SUMPRODUCT(--(Respostas!F124:F128<>""),Respostas!E124:E128) | I25: =IF(H25=0,"",G25/H25) | J25: =IF(I25="","Sem resposta",LOOKUP(I25,{0,0.5,1.5,2.5,3.5},{"L0 — Inicial","L1 — Em Desenvolvimento","L2 — Definido","L3 — Gerenciado","L4 — Otimizando"})) | K25: =IF(H25=0,0,D25*I25) | L25: =IF(H25=0,0,D25)
A26: P3-C4 | B26: Plataforma de Dados e Lakehouse | C26: P3 | D26: 1 | E26: =COUNT(Respostas!F129:F133) | F26: 5 | G26: =SUMPRODUCT(Respostas!F129:F133,Respostas!E129:E133) | H26: =SUMPRODUCT(--(Respostas!F129:F133<>""),Respostas!E129:E133) | I26: =IF(H26=0,"",G26/H26) | J26: =IF(I26="","Sem resposta",LOOKUP(I26,{0,0.5,1.5,2.5,3.5},{"L0 — Inicial","L1 — Em Desenvolvimento","L2 — Definido","L3 — Gerenciado","L4 — Otimizando"})) | K26: =IF(H26=0,0,D26*I26) | L26: =IF(H26=0,0,D26)
A27: P3-C5 | B27: Aplicações Agênticas | C27: P3 | D27: 1 | E27: =COUNT(Respostas!F134:F139) | F27: 6 | G27: =SUMPRODUCT(Respostas!F134:F139,Respostas!E134:E139) | H27: =SUMPRODUCT(--(Respostas!F134:F139<>""),Respostas!E134:E139) | I27: =IF(H27=0,"",G27/H27) | J27: =IF(I27="","Sem resposta",LOOKUP(I27,{0,0.5,1.5,2.5,3.5},{"L0 — Inicial","L1 — Em Desenvolvimento","L2 — Definido","L3 — Gerenciado","L4 — Otimizando"})) | K27: =IF(H27=0,0,D27*I27) | L27: =IF(H27=0,0,D27)
A28: P3-C6 | B28: Gestão de Identidades e Acessos | C28: P3 | D28: 1.1 | E28: =COUNT(Respostas!F140:F144) | F28: 5 | G28: =SUMPRODUCT(Respostas!F140:F144,Respostas!E140:E144) | H28: =SUMPRODUCT(--(Respostas!F140:F144<>""),Respostas!E140:E144) | I28: =IF(H28=0,"",G28/H28) | J28: =IF(I28="","Sem resposta",LOOKUP(I28,{0,0.5,1.5,2.5,3.5},{"L0 — Inicial","L1 — Em Desenvolvimento","L2 — Definido","L3 — Gerenciado","L4 — Otimizando"})) | K28: =IF(H28=0,0,D28*I28) | L28: =IF(H28=0,0,D28)
A29: P3-C7 | B29: Multi-Cloud e Portabilidade | C29: P3 | D29: 0.8 | E29: =COUNT(Respostas!F145:F149) | F29: 5 | G29: =SUMPRODUCT(Respostas!F145:F149,Respostas!E145:E149) | H29: =SUMPRODUCT(--(Respostas!F145:F149<>""),Respostas!E145:E149) | I29: =IF(H29=0,"",G29/H29) | J29: =IF(I29="","Sem resposta",LOOKUP(I29,{0,0.5,1.5,2.5,3.5},{"L0 — Inicial","L1 — Em Desenvolvimento","L2 — Definido","L3 — Gerenciado","L4 — Otimizando"})) | K29: =IF(H29=0,0,D29*I29) | L29: =IF(H29=0,0,D29)
A30: P3-C8 | B30: Desempenho e Escalabilidade | C30: P3 | D30: 1 | E30: =COUNT(Respostas!F150:F154) | F30: 5 | G30: =SUMPRODUCT(Respostas!F150:F154,Respostas!E150:E154) | H30: =SUMPRODUCT(--(Respostas!F150:F154<>""),Respostas!E150:E154) | I30: =IF(H30=0,"",G30/H30) | J30: =IF(I30="","Sem resposta",LOOKUP(I30,{0,0.5,1.5,2.5,3.5},{"L0 — Inicial","L1 — Em Desenvolvimento","L2 — Definido","L3 — Gerenciado","L4 — Otimizando"})) | K30: =IF(H30=0,0,D30*I30) | L30: =IF(H30=0,0,D30)
A31: P3-C9 | B31: FinOps e Otimização de Custos | C31: P3 | D31: 0.9 | E31: =COUNT(Respostas!F155:F159) | F31: 5 | G31: =SUMPRODUCT(Respostas!F155:F159,Respostas!E155:E159) | H31: =SUMPRODUCT(--(Respostas!F155:F159<>""),Respostas!E155:E159) | I31: =IF(H31=0,"",G31/H31) | J31: =IF(I31="","Sem resposta",LOOKUP(I31,{0,0.5,1.5,2.5,3.5},{"L0 — Inicial","L1 — Em Desenvolvimento","L2 — Definido","L3 — Gerenciado","L4 — Otimizando"})) | K31: =IF(H31=0,0,D31*I31) | L31: =IF(H31=0,0,D31)
A34: Score por pilar
A35: ID | B35: Nome | C35: Score | D35: Rótulo
A36: P1 | B36: Produtividade do Desenvolvedor | C36: =IF(SUM(L4:L12)=0,0,SUM(K4:K12)/SUM(L4:L12)) | D36: =LOOKUP(C36,{0,0.5,1.5,2.5,3.5},{"L0 — Inicial","L1 — Em Desenvolvimento","L2 — Definido","L3 — Gerenciado","L4 — Otimizando"})
A37: P2 | B37: Ciclo de Vida DevOps | C37: =IF(SUM(L13:L22)=0,0,SUM(K13:K22)/SUM(L13:L22)) | D37: =LOOKUP(C37,{0,0.5,1.5,2.5,3.5},{"L0 — Inicial","L1 — Em Desenvolvimento","L2 — Definido","L3 — Gerenciado","L4 — Otimizando"})
A38: P3 | B38: Plataforma de Aplicações | C38: =IF(SUM(L23:L31)=0,0,SUM(K23:K31)/SUM(L23:L31)) | D38: =LOOKUP(C38,{0,0.5,1.5,2.5,3.5},{"L0 — Inicial","L1 — Em Desenvolvimento","L2 — Definido","L3 — Gerenciado","L4 — Otimizando"})
A40: Overall (SUMPRODUCT sobre TODAS as capabilities, não é média dos pilares)
A41: Overall | C41: =IF(SUM(L4:L31)=0,0,SUM(K4:K31)/SUM(L4:L31)) | D41: =LOOKUP(C41,{0,0.5,1.5,2.5,3.5},{"L0 — Inicial","L1 — Em Desenvolvimento","L2 — Definido","L3 — Gerenciado","L4 — Otimizando"})
A43: Threshold de cobertura
A44: Respondidas | C44: =COUNT(Respostas!F2:F159)
A45: Aplicáveis | C45: 158
...
